<?xml version="1.0"?>
<robot name="RoRoverDiff">

<!-- ROS Control Plugin used to drive locomotion system and hook -->
  <gazebo>
    <plugin name="gazebo_ros_control" filename="libgazebo_ros_control.so">
      <!--robotNamespace>/rorover</robotNamespace-->
    </plugin>
  </gazebo>

<!-- Root Chassis -->
      <link name='chassis'>
        <collision>
          <origin xyz="0.0 0.0 0.0" rpy="0.0 0.0 0.0" />
          <geometry>
            <mesh filename="package://rorover_skid_steer/meshes/DifferentialChassis.stl" />
          </geometry>
          <surface>
            <bounce>
              <restitution_coefficient>0.35</restitution_coefficient>
              <threshold>0.025</threshold>
            </bounce>
          </surface>
        </collision>
        <visual>
          <origin xyz="0.0 0.0 0.0" rpy="0.0 0.0 0.0" />
          <geometry>
            <mesh filename="package://rorover_skid_steer/meshes/DifferentialChassis.stl" />
          </geometry>
        </visual>
      <inertial>
        <mass value="5.306" />
        <origin xyz="0.123149 0.0 0.06677"
                rpy="0.0 -0.2556907354 0.0" />
        <inertia
 	  ixx="0.221974787" ixy="0.0" ixz="0.0"
	  iyy="0.341467333" iyz="0.0"
	  izz="0.454114912" />
      </inertial>
      </link>

<!-- Left Differential Suspension Arm -->
      <link name='left_arm'>
        <collision>
          <origin xyz="0.0 0.0 0.0" rpy="0.0 0.0 0.0" />
          <geometry>
            <mesh filename="package://rorover_skid_steer/meshes/SuspensionArm.stl" />
          </geometry>
          <surface>
            <bounce>
              <restitution_coefficient>0.35</restitution_coefficient>
              <threshold>0.025</threshold>
            </bounce>
          </surface>
        </collision>
        <visual>
          <origin xyz="0.0 0.0 0.0" rpy="0.0 0.0 0.0" />
          <geometry>
            <mesh filename="package://rorover_skid_steer/meshes/SuspensionArm.stl" />
          </geometry>
        </visual>
      <inertial>
        <mass value="0.906" />
        <origin xyz="0.0 0.0 0.004832"
                rpy="0.0 0.0 0.0" />
        <inertia
 	  ixx="0.000742332" ixy="0.0" ixz="0.0"
	  iyy="0.018848023" iyz="0.0"
	  izz="0.019383356" />
      </inertial>
      </link>

      <joint type="revolute" name="left_arm_hinge">
	<origin xyz="0.0 0.36 0.065"
                rpy="0.0 0.0 0.0" />
        <child link="left_arm" />
        <parent link="chassis" />
        <axis xyz="0 1 0" />
        <limit lower="-0.2" upper="0.2" effort="100" velocity="1.0" />
        <dynamics damping="0.1" />
      </joint>

<!-- Right Differential Suspension Arm -->
      <link name='right_arm'>
        <collision>
          <origin xyz="0.0 0.0 0.0" rpy="0.0 0.0 0.0" />
          <geometry>
            <mesh filename="package://rorover_skid_steer/meshes/SuspensionArm.stl" />
          </geometry>
          <surface>
            <bounce>
              <restitution_coefficient>0.35</restitution_coefficient>
              <threshold>0.025</threshold>
            </bounce>
          </surface>
        </collision>
        <visual>
          <origin xyz="0.0 0.0 0.0" rpy="0.0 0.0 0.0" />
          <geometry>
            <mesh filename="package://rorover_skid_steer/meshes/SuspensionArm.stl" />
          </geometry>
        </visual>
      <inertial>
        <mass value="0.906" />
        <origin xyz="0.0 0.0 0.004832"
                rpy="0.0 0.0 0.0" />
        <inertia
 	  ixx="0.000742332" ixy="0.0" ixz="0.0"
	  iyy="0.018848023" iyz="0.0"
	  izz="0.019383356" />
      </inertial>
      </link>

      <joint type="revolute" name="right_arm_hinge">
	<origin xyz="0.0 -0.36 0.065"
                rpy="0.0 0.0 0.0" />
        <child link="right_arm" />
        <parent link="chassis" />
        <axis xyz="0 -1 0" />
        <limit lower="-0.2" upper="0.2" effort="100" velocity="1.0" />
        <mimic joint="left_arm_hinge" />
      </joint>

<!-- Mimic Joint plugin to create differential suspension -->
  <gazebo>
    <plugin name="gazebo_mimic_joint" filename="libroboticsgroup_gazebo_mimic_joint_plugin.so">
      <joint>left_arm_hinge</joint>
        <mimicJoint>right_arm_hinge</mimicJoint>
        <multiplier>1.0</multiplier>
        <sensitiveness>0.0</sensitiveness>   
        <maxEffort>100.0</maxEffort>             
      </plugin>
  </gazebo>

<!-- Left Front Steering Arm -->
      <link name='left_front_steering'>
        <collision>
          <origin xyz="0.0 0.0 0.0" rpy="0.0 0.0 0.0" />
          <geometry>
            <mesh filename="package://rorover_skid_steer/meshes/SteeringArm.stl" />
          </geometry>
          <surface>
            <bounce>
              <restitution_coefficient>0.35</restitution_coefficient>
              <threshold>0.025</threshold>
            </bounce>
          </surface>
        </collision>
        <visual>
          <origin xyz="0.0 0.0 0.0" rpy="0.0 0.0 0.0" />
          <geometry>
            <mesh filename="package://rorover_skid_steer/meshes/SteeringArm.stl" />
          </geometry>
        </visual>
      <inertial>
        <mass value="0.420" />
        <origin xyz="0.0 0.030299 -0.082164"
                rpy="-0.0218166156 0.0 0.0" />
        <inertia
 	  ixx="0.001752153" ixy="0.0" ixz="0.0"
	  iyy="0.001383863" iyz="0.0"
	  izz="0.000702665" />
      </inertial>
      </link>

      <joint type="fixed" name="left_front_steering_joint">
	<origin xyz="-0.24 0.0 -0.01"
                rpy="0.0 0.0 3.1416" />
        <child link="left_front_steering" />
        <parent link="left_arm" />
      </joint>

<!-- Left Rear Steering Arm -->
      <link name='left_rear_steering'>
        <collision>
          <origin xyz="0.0 0.0 0.0" rpy="0.0 0.0 0.0" />
          <geometry>
            <mesh filename="package://rorover_skid_steer/meshes/SteeringArm.stl" />
          </geometry>
          <surface>
            <bounce>
              <restitution_coefficient>0.35</restitution_coefficient>
              <threshold>0.025</threshold>
            </bounce>
          </surface>
        </collision>
        <visual>
          <origin xyz="0.0 0.0 0.0" rpy="0.0 0.0 0.0" />
          <geometry>
            <mesh filename="package://rorover_skid_steer/meshes/SteeringArm.stl" />
          </geometry>
        </visual>
      <inertial>
        <mass value="0.420" />
        <origin xyz="0.0 0.030299 -0.082164"
                rpy="-0.0218166156 0.0 0.0" />
        <inertia
 	  ixx="0.001752153" ixy="0.0" ixz="0.0"
	  iyy="0.001383863" iyz="0.0"
	  izz="0.000702665" />
      </inertial>
      </link>

      <joint type="fixed" name="left_rear_steering_joint">
	<origin xyz="0.24 0.0 -0.01"
                rpy="0.0 0.0 3.1416" />
        <child link="left_rear_steering" />
        <parent link="left_arm" />
      </joint>

<!-- Right Front Steering Arm -->
      <link name='right_front_steering'>
        <collision>
          <origin xyz="0.0 0.0 0.0" rpy="0.0 0.0 0.0" />
          <geometry>
            <mesh filename="package://rorover_skid_steer/meshes/SteeringArm.stl" />
          </geometry>
          <surface>
            <bounce>
              <restitution_coefficient>0.35</restitution_coefficient>
              <threshold>0.025</threshold>
            </bounce>
          </surface>
        </collision>
        <visual>
          <origin xyz="0.0 0.0 0.0" rpy="0.0 0.0 0.0" />
          <geometry>
            <mesh filename="package://rorover_skid_steer/meshes/SteeringArm.stl" />
          </geometry>
        </visual>
      <inertial>
        <mass value="0.420" />
        <origin xyz="0.0 0.030299 -0.082164"
                rpy="-0.0218166156 0.0 0.0" />
        <inertia
 	  ixx="0.001752153" ixy="0.0" ixz="0.0"
	  iyy="0.001383863" iyz="0.0"
	  izz="0.000702665" />
      </inertial>
      </link>

      <joint type="fixed" name="right_front_steering_joint">
	<origin xyz="-0.24 0.0 -0.01"
                rpy="0.0 0.0 0.0" />
        <child link="right_front_steering" />
        <parent link="right_arm" />
      </joint>

<!-- Right Rear Steering Arm -->
      <link name='right_rear_steering'>
        <collision>
          <origin xyz="0.0 0.0 0.0" rpy="0.0 0.0 0.0" />
          <geometry>
            <mesh filename="package://rorover_skid_steer/meshes/SteeringArm.stl" />
          </geometry>
          <surface>
            <bounce>
              <restitution_coefficient>0.35</restitution_coefficient>
              <threshold>0.025</threshold>
            </bounce>
          </surface>
        </collision>
        <visual>
          <origin xyz="0.0 0.0 0.0" rpy="0.0 0.0 0.0" />
          <geometry>
            <mesh filename="package://rorover_skid_steer/meshes/SteeringArm.stl" />
          </geometry>
        </visual>
      <inertial>
        <mass value="0.420" />
        <origin xyz="0.0 0.030299 -0.082164"
                rpy="-0.0218166156 0.0 0.0" />
        <inertia
 	  ixx="0.001752153" ixy="0.0" ixz="0.0"
	  iyy="0.001383863" iyz="0.0"
	  izz="0.000702665" />
      </inertial>
      </link>

      <joint type="fixed" name="right_rear_steering_joint">
	<origin xyz="0.24 0.0 -0.01"
                rpy="0.0 0.0 0.0" />
        <child link="right_rear_steering" />
        <parent link="right_arm" />
      </joint>

<!-- Left Front Wheel link, joint and transmission -->
      <link name="left_front_wheel">
        <collision name="collision">
          <origin xyz="0.0 0.0 0.0" rpy="0.0 0.0 0.0" />
          <geometry>
            <cylinder length="0.117" radius="0.1" />
          </geometry>
          <surface>
            <bounce>
              <restitution_coefficient>0.35</restitution_coefficient>
              <threshold>0.025</threshold>
            </bounce>
          </surface>
        </collision>
        <visual name="visual">
          <origin xyz="0.0 0.0 0.0" rpy="0.0 0.0 0.0" />
          <geometry>
            <mesh filename="package://rorover_skid_steer/meshes/wheel_unders.dae" />
          </geometry>
        </visual>
        <inertial>
          <mass value="0.454"/>
	  <origin zyx="0.0 0.0 0.001805" rpy="0.0 0.0 0.5167919915" />
	  <inertia 
	    ixx="0.001983016" ixy="0.0" ixz="0.0"
	    iyy="0.001983016" iyz="0.0"
	    izz="0.00297862" />
        </inertial>
      </link>

      <joint type="continuous" name="left_front_wheel_hinge">
	<origin xyz="0.0 -0.0315 -0.130" rpy="1.5707 0.0 0.0" />
        <child link="left_front_wheel" />
        <parent link="left_front_steering" />
        <axis xyz="0 0 1" />
        <dynamics damping="0.1" />
      </joint>

  <transmission name="left_front_trans">
    <type>transmission_interface/SimpleTransmission</type>
    <joint name="left_front_wheel_hinge">
      <hardwareInterface>hardware_interface/VelocityJointInterface</hardwareInterface>
    </joint>
    <actuator name="left_front_motor">
      <mechanicalReduction>1</mechanicalReduction>
    </actuator>
  </transmission>

<!-- Left Rear Wheel link, joint and transmission -->
      <link name="left_rear_wheel">
        <collision name="collision">
          <origin xyz="0.0 0.0 0.0" rpy="0.0 0.0 0.0" />
          <geometry>
            <cylinder length="0.117" radius="0.1" />
          </geometry>
          <surface>
            <bounce>
              <restitution_coefficient>0.35</restitution_coefficient>
              <threshold>0.025</threshold>
            </bounce>
          </surface>
        </collision>
        <visual name="visual">
          <origin xyz="0.0 0.0 0.0" rpy="0.0 0.0 0.0" />
          <geometry>
            <mesh filename="package://rorover_skid_steer/meshes/wheel_unders.dae" />
          </geometry>
        </visual>
        <inertial>
          <mass value="0.454"/>
	  <origin zyx="0.0 0.0 0.001805" rpy="0.0 0.0 0.5167919915" />
	  <inertia 
	    ixx="0.001983016" ixy="0.0" ixz="0.0"
	    iyy="0.001983016" iyz="0.0"
	    izz="0.00297862" />
        </inertial>
      </link>

      <joint type="continuous" name="left_rear_wheel_hinge">
	<origin xyz="0.0 -0.0315 -0.130" rpy="1.5707 0.0 0.0" />
        <child link="left_rear_wheel" />
        <parent link="left_rear_steering" />
        <axis xyz="0 0 1" />
        <dynamics damping="0.1" />
      </joint>

  <transmission name="left_rear_trans">
    <type>transmission_interface/SimpleTransmission</type>
    <joint name="left_rear_wheel_hinge">
      <hardwareInterface>hardware_interface/VelocityJointInterface</hardwareInterface>
    </joint>
    <actuator name="left_rear_motor">
      <mechanicalReduction>1</mechanicalReduction>
    </actuator>
  </transmission>







<!-- Right Front Wheel link, joint and transmission -->
      <link name="right_front_wheel">
        <collision name="collision">
          <origin xyz="0.0 0.0 0.0" rpy="0.0 0.0 0.0" />
          <geometry>
            <cylinder length="0.117" radius="0.1" />
          </geometry>
          <surface>
            <bounce>
              <restitution_coefficient>0.35</restitution_coefficient>
              <threshold>0.025</threshold>
            </bounce>
          </surface>
        </collision>
        <visual name="visual">
          <origin xyz="0.0 0.0 0.0" rpy="0.0 0.0 0.0" />
          <geometry>
            <mesh filename="package://rorover_skid_steer/meshes/wheel_unders.dae" />
          </geometry>
        </visual>
        <inertial>
          <mass value="0.454"/>
	  <origin zyx="0.0 0.0 0.001805" rpy="0.0 0.0 0.5167919915" />
	  <inertia 
	    ixx="0.001983016" ixy="0.0" ixz="0.0"
	    iyy="0.001983016" iyz="0.0"
	    izz="0.00297862" />
        </inertial>
      </link>

      <joint type="continuous" name="right_front_wheel_hinge">
	<origin xyz="0.0 -0.0315 -0.130" rpy="1.5707 0.0 0.0" />
        <child link="right_front_wheel" />
        <parent link="right_front_steering" />
        <axis xyz="0 0 -1" />
        <dynamics damping="0.1" />
      </joint>

  <transmission name="right_front_trans">
    <type>transmission_interface/SimpleTransmission</type>
    <joint name="right_front_wheel_hinge">
      <hardwareInterface>hardware_interface/VelocityJointInterface</hardwareInterface>
    </joint>
    <actuator name="right_front_motor">
      <mechanicalReduction>1</mechanicalReduction>
    </actuator>
  </transmission>

<!-- Right Rear Wheel link, joint and transmission -->
      <link name="right_rear_wheel">
        <collision name="collision">
          <origin xyz="0.0 0.0 0.0" rpy="0.0 0.0 0.0" />
          <geometry>
            <cylinder length="0.117" radius="0.1" />
          </geometry>
          <surface>
            <bounce>
              <restitution_coefficient>0.35</restitution_coefficient>
              <threshold>0.025</threshold>
            </bounce>
          </surface>
        </collision>
        <visual name="visual">
          <origin xyz="0.0 0.0 0.0" rpy="0.0 0.0 0.0" />
          <geometry>
            <mesh filename="package://rorover_skid_steer/meshes/wheel_unders.dae" />
          </geometry>
        </visual>
        <inertial>
          <mass value="0.454"/>
	  <origin zyx="0.0 0.0 0.001805" rpy="0.0 0.0 0.5167919915" />
	  <inertia 
	    ixx="0.001983016" ixy="0.0" ixz="0.0"
	    iyy="0.001983016" iyz="0.0"
	    izz="0.00297862" />
        </inertial>
      </link>

      <joint type="continuous" name="right_rear_wheel_hinge">
	<origin xyz="0.0 -0.0315 -0.130" rpy="1.5707 0.0 0.0" />
        <child link="right_rear_wheel" />
        <parent link="right_rear_steering" />
        <axis xyz="0 0 -1" />
        <dynamics damping="0.1" />
      </joint>

  <transmission name="right_rear_trans">
    <type>transmission_interface/SimpleTransmission</type>
    <joint name="right_rear_wheel_hinge">
      <hardwareInterface>hardware_interface/VelocityJointInterface</hardwareInterface>
    </joint>
    <actuator name="right_rear_motor">
      <mechanicalReduction>1</mechanicalReduction>
    </actuator>
  </transmission>

<!-- Roll On Roll Off Hook -->
      <link name="hook">
        <collision name="collision">
          <origin xyz="0.0 0.0 0.0" rpy="0.0 0.0 0.0" />
          <geometry>
            <mesh filename="package://rorover_skid_steer/meshes/Hook_Arm_v0.2_collision.stl" />
          </geometry>
          <surface>
            <bounce>
              <restitution_coefficient>0.35</restitution_coefficient>
              <threshold>0.025</threshold>
            </bounce>
          </surface>
        </collision>
        <visual name="visual">
          <origin xyz="0.0 0.0 0.0" rpy="0.0 0.0 0.0" />
          <geometry>
            <mesh filename="package://rorover_skid_steer/meshes/Hook_Arm_v0.2_collision.stl" />
          </geometry>
        </visual>
        <inertial>
          <mass value="0.702" />
	  <origin xyz="0.0 0.1826163 0.027687"
                  rpy="0.3199188519 0.0 0.0" />
	  <inertia 
	    ixx="0.011657837" ixy="0.0" ixz="0.0"
	    iyy="0.001605345" iyz="0.0"
	    izz="0.010187828" />
        </inertial>
      </link>

      <joint type="revolute" name="joint1">
	<origin xyz="-0.13 0.0 0.0" rpy="0.0 0.0 -1.5707" />
        <child link="hook" />
        <parent link="chassis" />
        <axis xyz="1 0 0" />
        <limit lower="-0.0" upper="2.617993878" effort="100" velocity="0.0001" />
        <safety_controller_not k_velocity="100" k_position="100" soft_lower_limit="0.0" soft_upper_limit="2.517" />
      </joint>

  <transmission name="hook_trans">
    <type>transmission_interface/SimpleTransmission</type>
    <joint name="joint1">
      <hardwareInterface>hardware_interface/EffortJointInterface</hardwareInterface>
    </joint>
    <actuator name="hook_motor">
      <mechanicalReduction>50</mechanicalReduction>
    </actuator>
  </transmission>

</robot>
